#VRML_SIM R2019a utf8
WorldInfo {
}
Viewpoint {
  orientation 0.027466958969742772 -0.9926749512866669 -0.11765206013057285 3.6491517094816324
  position 0.41359249135603954 0.5932422960990826 -1.0270875733444274
}
TexturedBackground {
}
TexturedBackgroundLight {
}
Floor {
}
Solid {
  translation 0 0.25 0
  children [
    Shape {
      appearance PBRAppearance {
        baseColor 0 0 1
        roughness 1
      }
      geometry Cylinder {
        height 0.5
        radius 0.03
      }
    }
    HingeJoint {
      jointParameters HingeJointParameters {
        position -4.255036480359789e-58
        axis 0 1 0
        anchor 0 0.225 0
        minStop -0.785
        maxStop 0.785
        dampingConstant 0.2
        staticFriction 0.01
      }
      endPoint Solid {
        translation -2.7755575615628895e-17 0.255 -3.4694469519536103e-18
        rotation -0.12403473458918009 4.016785919056577e-36 0.9922778767136712 4.386076908609537e-22
        children [
          Shape {
            appearance PBRAppearance {
              baseColor 1 0 0
              roughness 1
            }
            geometry Box {
              size 0.8 0.01 0.1
            }
          }
        ]
        physics Physics {
        }
        linearVelocity -1.0099659396775103e-25 -1.2139210832630653e-07 -1.2624574243333194e-26
        angularVelocity -4.209920086843472e-25 1.2677586874217443e-55 3.367936071052463e-24
      }
    }
    HingeJoint {
      jointParameters HingeJointParameters {
        axis 0 0 1
        anchor 0 0 -0.035
      }
      endPoint Solid {
        translation 0 0 -0.035
        children [
          Shape {
            appearance PBRAppearance {
              baseColor 0 1 0
              roughness 1
            }
            geometry Box {
              size 0.1 0.03 0.01
            }
          }
        ]
        name "solid(1)"
        physics Physics {
        }
        linearVelocity 0 -1.213921088378956e-07 0
      }
    }
  ]
}
